<?xml version="1.0"?>
<robot name="robot">
    <link name="base_link">
        <visual>
            <geometry>
                <cylinder length="1" radius="0.25"/>
            </geometry>
            <origin rpy="0 0 0" xyz="0 0 0.5"/>
        </visual>
    </link>
    
    <joint name="base_to_plate" type="prismatic">
        <parent link="base_link"/>
        <child link="plate"/>
        <origin rpy="0 0 0" xyz="0 0 0"/>
        <axis xyz="0 0 1"/>
        <limit effort="1000.0" lower="0" upper="1" velocity="0.5"/>
    </joint>
    
    <link name="plate">
        <visual>
            <geometry>
                <box size="0.7 0.7 0.05"/>
            </geometry>
            <origin rpy="0 0 0" xyz="0 0 0.025"/>
        </visual>
    </link>
</robot>