<robot name="simple_niryo">

    <material name="blue">
        <color rgba="0.192157 0.643137 0.866667 1"/>
    </material>

    <material name="black">
        <color rgba="0.12 0.12 0.12 1"/>
    </material>

    <material name="silver">
        <color rgba="0.73 0.75 0.75 1"/>
    </material>

    <!-- WORLD -->
    <link name="world"/>

    <!-- [REQUIRED] BASE LINK -->
    <link name="base_link">
        <visual>
            <geometry>
                <box size="0.25 0.25 0.15"/>
            </geometry>
            <origin rpy="0 0 0" xyz="0 0 0.075"/>
            <material name="blue"/>
        </visual>
    </link>
    <joint name="world_to_base_link_joint" type="fixed">
        <parent link="world"/>
        <child link="base_link"/>
        <origin rpy="0 0 0" xyz="0 0 0"/>
    </joint>

    <!-- [OPTIONAL] VISUAL FOR SHOULDER LINK JOINT -->
    <link name="shoulder_juncture">
        <visual>
            <geometry>
                <cylinder length="0.03" radius="0.11"/>
            </geometry>
            <origin xyz="0 0 0.015"/>
            <material name="black"/>
        </visual>
    </link>
    <joint name="shoulder_juncture_joint" type="fixed">
        <parent link="base_link"/>
        <child link="shoulder_juncture"/>
        <origin rpy="0 0 0" xyz="0 0 0.15"/>
    </joint>

    <!-- SHOULDER LINK -->
    <link name="shoulder_link">
        <visual>
            <geometry>
                <cylinder length="0.15" radius="0.1"/>
            </geometry>
            <origin rpy="0 0 0" xyz="0 0 0.075"/>
            <material name="blue"/>
        </visual>
    </link>
    <joint name="base_to_shoulder_joint" type="revolute">
        <parent link="base_link"/>
        <child link="shoulder_link"/>
        <origin rpy="0 0 0" xyz="0 0 0.15"/>
        <axis xyz="0 0 1"/>
        <limit effort="1000.0" lower="-2.617994" upper="2.617994" velocity="0.5"/>
    </joint>

    <!-- [OPTIONAL] VISUAL FOR ELBOW LINK JOINT -->
    <link name="elbow_juncture">
        <visual>
            <geometry>
                <sphere radius="0.095"/>
            </geometry>
            <material name="black"/>
        </visual>
    </link>
    <joint name="elbow_juncture_joint" type="fixed">
        <parent link="shoulder_link"/>
        <child link="elbow_juncture"/>
        <origin rpy="0 0 0" xyz="0 0 0.15"/>
    </joint>

    <!-- ELBOW LINK -->
    <link name="elbow_link">
        <visual>
            <geometry>
                <cylinder length="0.4" radius="0.04"/>
            </geometry>
            <origin rpy="0 1.570796 0" xyz="0.2 0 0"/>
            <material name="silver"/>
        </visual>
    </link>
    <joint name="shoulder_to_elbow_joint" type="revolute">
        <parent link="shoulder_link"/>
        <child link="elbow_link"/>
        <origin rpy="1.570796 0 0" xyz="0 0 0.15"/>
        <axis xyz="0 0 1"/>
        <limit effort="1000.0" lower="-0.1745329" upper="3.490659" velocity="0.5"/>
    </joint>

    <!-- [OPTIONAL] VISUAL FOR WRIST LINK JOINT -->
    <link name="wrist_juncture">
        <visual>
            <geometry>
                <cylinder length="0.08" radius="0.05"/>
            </geometry>
            <origin rpy="0 0 0" xyz="0 0 0"/>
            <material name="blue"/>
        </visual>
    </link>
    <joint name="wrist_juncture_joint" type="fixed">
        <parent link="elbow_link"/>
        <child link="wrist_juncture"/>
        <origin rpy="0 0 0" xyz="0.4 0 0"/>
    </joint>

    <!-- WRIST LINK -->
    <link name="wrist_link">
        <visual>
            <geometry>
                <cylinder length="0.3" radius="0.04"/>
            </geometry>
            <origin rpy="0 1.570796 0" xyz="0.15 0 0"/>
            <material name="silver"/>
        </visual>
    </link>
    <joint name="elbow_to_wrist_joint" type="revolute">
        <parent link="elbow_link"/>
        <child link="wrist_link"/>
        <origin rpy="0 0 0" xyz="0.4 0 0"/>
        <axis xyz="0 0 1"/>
        <limit effort="1000.0" lower="-1.745329" upper="1.745329" velocity="0.5"/>
    </joint>

    <!-- [OPTIONAL] VISUAL FOR KNUCKLE LINK JOINT -->
    <link name="knuckle_juncture">
        <visual>
            <geometry>
                <cylinder length="0.08" radius="0.05"/>
            </geometry>
            <origin rpy="0 0 0" xyz="0 0 0"/>
            <material name="blue"/>
        </visual>
    </link>
    <joint name="knuckle_juncture_joint" type="fixed">
        <parent link="wrist_link"/>
        <child link="knuckle_juncture"/>
        <origin rpy="0 0 0" xyz="0.3 0 0"/>
    </joint>

    <!-- KNUCKLE LINK -->
    <link name="knuckle_link">
        <visual>
            <geometry>
                <box size="0.08 0.075 0.04"/>
            </geometry>
            <origin rpy="0 0 0" xyz="0.04 0 0"/>
            <material name="silver"/>
        </visual>
    </link>
    <joint name="wrist_to_hand_joint" type="revolute">
        <parent link="wrist_link"/>
        <child link="knuckle_link"/>
        <origin rpy="0 0 0" xyz="0.3 0 0"/>
        <axis xyz="0 0 1"/>
        <limit effort="1000.0" lower="-1.570796" upper="1.570796" velocity="0.5"/>
    </joint>

    <!-- [OPTIONAL] VISUAL FOR FINGER LINK JOINT -->
    <link name="finger_juncture">
        <visual>
            <geometry>
                <box size="0.03 0.08 0.045"/>
            </geometry>
            <material name="black"/>
        </visual>
    </link>
    <joint name="finger_juncture_joint" type="fixed">
        <parent link="knuckle_link"/>
        <child link="finger_juncture"/>
        <origin xyz="0.08 0 0"/>
    </joint>

    <!-- LEFT FINGER LINK -->
    <link name="left_finger_link">
        <visual>
            <geometry>
                <mesh filename="package://urdf_tutorial/meshes/l_finger.dae"/>
            </geometry>
            <origin xyz="0.01 0.02 0"/>
        </visual>
    </link>
    <joint name="knuckle_to_left_finger_joint" type="revolute">
        <parent link="knuckle_link"/>
        <child link="left_finger_link"/>
        <origin rpy="0 0 0" xyz="0.08 0 0"/>
        <axis xyz="0 0 1"/>
        <limit effort="1000.0" lower="-0.17" upper="0.548" velocity="0.5"/>
    </joint>

    <!-- RIGHT FINGER LINK -->
    <link name="right_finger_link">
        <visual>
            <geometry>
                <mesh filename="package://urdf_tutorial/meshes/l_finger.dae"/>
            </geometry>
            <origin rpy="3.141593 0 0" xyz="0.01 -0.02 0"/>
        </visual>
    </link>
    <joint name="knuckle_to_right_finger_joint" type="revolute">
        <parent link="knuckle_link"/>
        <child link="right_finger_link"/>
        <origin rpy="0 0 0" xyz="0.08 0 0"/>
        <axis xyz="0 0 1"/>
        <limit effort="1000.0" lower="-0.548" upper="0.17" velocity="0.5"/>
    </joint>

</robot>
